Workbook

Sheet Resumen
A1: RecyTrack · Sprint Backlog del proyecto
A2: Una hoja por sprint. Scrum Master: Matías Bustamante. Fechas según la carta Gantt del informe de la Fase 1, con la semana de receso de Fiestas Patrias.
A4: Sprint | B4: Semanas | C4: Fechas | D4: Objetivo | E4: Estado | F4: Historias | G4: Puntos comprometidos | H4: Puntos terminados | I4: Avance
A5: S0 | B5: 3 y 4 | C5: 31-08 al 11-09 | D5: Validación en terreno del problema y de la ronda diaria con la viña. Sprint de levantamiento, sin historias de software. | E5: Por confirmar | F5: — | G5: — | H5: — | I5: —
A6: S1 | B6: 5 y 6 | C6: 21-09 al 02-10 | D6: Arquitectura base, autenticación y roles, y primeras versiones del registro por QR, la validación por contenedor, los avisos y los documentos PDF. | E6: =S1!B6 -> Cerrado | F6: 5 | G6: =S1!B7 -> 11 | H6: =S1!B8 -> 11 | I6: =IF(G6=0,0,H6/G6) -> 1
A7: S2 | B7: 7 y 8 | C7: 05-10 al 16-10 | D7: Que el administrador pueda configurar la planta desde el panel web: crear las áreas, registrar los contenedores de cada punto limpio con sus QR, ver a las personas por área y asignar al validador y su suplente. | E7: =S2!B6 -> En curso | F7: 7 | G7: =S2!B7 -> 31 | H7: =S2!B8 -> 0 | I7: =IF(G7=0,0,H7/G7) -> 0
A8: S3 | B8: 9 y 10 | C8: 19-10 al 30-10 | D8: Que el colaborador registre en cualquier punto limpio sumando a su área, y que el validador haga la ronda desde su propia vista. | E8: =S3!B6 -> Planificado | F8: 9 | G8: =S3!B7 -> 33 | H8: =S3!B8 -> 0 | I8: =IF(G8=0,0,H8/G8) -> 0
A9: S4 | B9: 11 y 12 | C9: 02-11 al 13-11 | D9: Cerrar la cadena con el registro de retiros desde el panel, emitir el reporte y los certificados del mes, y dejar la planta lista para iniciar el piloto. | E9: =S4!B6 -> Planificado | F9: 9 | G9: =S4!B7 -> 30 | H9: =S4!B8 -> 0 | I9: =IF(G9=0,0,H9/G9) -> 0
A10: S5 | B10: 13 y 14 | C10: 16-11 al 27-11 | D10: Completar el panel con resumen y rondas, y activar las campañas y el ranking de áreas por participación, con el piloto en curso. | E10: =S5!B6 -> Planificado | F10: 7 | G10: =S5!B7 -> 25 | H10: =S5!B8 -> 0 | I10: =IF(G10=0,0,H10/G10) -> 0
A11: S6 | B11: 15 a 17 | C11: 30-11 al 18-12 | D11: Cerrar el piloto, medir las métricas comprometidas, corregir errores y terminar los detalles pendientes. | E11: =S6!B6 -> Planificado | F11: 7 | G11: =S6!B7 -> 20 | H11: =S6!B8 -> 0 | I11: =IF(G11=0,0,H11/G11) -> 0
A12: Piloto | B12: 13 a 17 | C12: 16-11 al 18-12 | D12: Cuatro semanas de uso en la planta, en paralelo con S5 y S6. Metas: 70 % de rondas completadas y 60 % de participación. | E12: Planificado | F12: — | G12: — | H12: — | I12: —
A13: Total | F13: =SUM(F6:F11) -> 44 | G13: =SUM(G6:G11) -> 150 | H13: =SUM(H6:H11) -> 11 | I13: =IF(G13=0,0,H13/G13) -> 0.073333333
A15: Las historias de cada sprint vienen del Product Backlog. Las que quedan para después del piloto no se asignan a ningún sprint. En el S2 se terminaron también historias planificadas para S3, S4 y S5; en sus hojas aparecen como Hecho con la fecha real.

Sheet S1
A1: RecyTrack · Sprint Backlog · Sprint 1
A3: Semanas | B3: 5 y 6
A4: Fechas | B4: 21 de septiembre al 2 de octubre de 2026
A5: Objetivo del sprint | B5: Arquitectura base, autenticación y roles, y primeras versiones del registro por QR, la validación por contenedor, los avisos y los documentos PDF.
A6: Estado del sprint | B6: Cerrado
A7: Puntos comprometidos | B7: =SUM(D12:D16) -> 11
A8: Puntos terminados | B8: =SUMIF(F12:F16,"Hecho",D12:D16) -> 11
A9: Avance | B9: =IF(B7=0,0,B8/B7) -> 1
A10: Historias del sprint | J10: Resultado del sprint
A11: ID | B11: Historia de usuario | C11: Prioridad | D11: Puntos | E11: Responsable | F11: Estado | G11: Fecha de término | H11: Criterios de aceptación | J11: Se terminaron las historias del sprint y quedaron primeras versiones funcionando del escaneo QR, la validación por contenedor, el certificado y el reporte mensual, el ranking y la misión. Esas primeras versiones se ajustan al modelo de áreas en los sprints siguientes y por eso sus historias figuran en el sprint en que se terminan.
A12: PB-01 | B12: Como colaborador, quiero indicar el material y la talla de la bolsa con una referencia visual, para que la app estime los kilos sin que yo pese nada. | C12: Must | D12: 3 | E12: Álvaro Jaña | F12: Hecho | G12: 46289 | H12: Si el contenedor es de un material, queda fijado. Tallas S, M, L y XL. Los kilos salen de la tabla y no se pueden escribir a mano.
A13: PB-02 | B13: Como colaborador, quiero escribir el código impreso bajo el QR cuando la cámara no lo lee, para no perder el registro. | C13: Must | D13: 1 | E13: Álvaro Jaña | F13: Hecho | G13: 46286 | H13: El código manual se valida igual que el escaneado.
A14: PB-03 | B14: Como colaborador, quiero ver el historial de mis depósitos y el estado de cada uno, para saber si fueron validados. | C14: Must | D14: 3 | E14: Álvaro Jaña | F14: Hecho | G14: 46289 | H14: Cada depósito muestra estado y fecha de cada etapa. Se agrupa por mes.
A15: PB-04 | B15: Como colaborador, quiero entrar con mi cuenta de Google o de Microsoft, para no tener que recordar otra contraseña. | C15: Should | D15: 3 | E15: Álvaro Jaña | F15: Hecho | G15: 46295 | H15: Los botones funcionan en la versión web e instalada. La primera vez se crea la cuenta como colaborador.
A16: PB-05 | B16: Como colaborador, quiero recibir un aviso cuando mi depósito es validado, rechazado o certificado, para saber que mi aporte cuenta. | C16: Should | D16: 1 | E16: Álvaro Jaña | F16: Hecho | G16: 46288 | H16: El aviso aparece en la campana con contador de nuevos.
A18: Tareas
A19: Tarea | B19: Descripción | C19: Historia | D19: Horas est. | E19: Responsable | F19: Estado | G19: Fecha | H19: Issue / PR · Notas
A20: T1-01 | B20: Convertir la app en aplicación web instalable (PWA) | C20: Transversal | E20: Álvaro Jaña | F20: Hecho | G20: 46286
A21: T1-02 | B21: Escáner QR con la cámara del navegador y certificado PDF descargable | C21: PB-16 (1.ª versión) | E21: Álvaro Jaña | F21: Hecho | G21: 46286
A22: T1-03 | B22: Pantalla Mi cuenta y QR del contenedor visible para el administrador | C22: Transversal | E22: Álvaro Jaña | F22: Hecho | G22: 46286
A23: T1-04 | B23: Roles validados por código en el servidor: nadie se asigna permisos | C23: Transversal | E23: Álvaro Jaña | F23: Hecho | G23: 46287
A24: T1-05 | B24: Misión con incentivo editable por el administrador | C24: PB-32 (1.ª versión) | E24: Álvaro Jaña | F24: Hecho | G24: 46287
A25: T1-06 | B25: Barra de navegación inferior para quien recicla | C25: Transversal | E25: Álvaro Jaña | F25: Hecho | G25: 46287
A26: T1-07 | B26: Actualizar README y SETUP-FIREBASE al estado de la implementación | C26: Transversal | E26: Álvaro Jaña | F26: Hecho | G26: 46287
A27: T1-08 | B27: Misión semanal del sistema con EcoPuntos | C27: PB-36 (1.ª versión) | E27: Álvaro Jaña | F27: Hecho | G27: 46288
A28: T1-09 | B28: Inicio de sesión con Google | C28: PB-04 | E28: Álvaro Jaña | F28: Hecho | G28: 46288
A29: T1-10 | B29: Avisos de avance dentro de la app para cada rol | C29: PB-05 | E29: Álvaro Jaña | F29: Hecho | G29: 46288
A30: T1-11 | B30: Avisos como banner emergente en el momento del evento | C30: PB-05 | E30: Álvaro Jaña | F30: Hecho | G30: 46288
A31: T1-12 | B31: Registro por talla de bolsa en vez de peso | C31: PB-01 | E31: Álvaro Jaña | F31: Hecho | G31: 46289
... A46: T1-27 | B46: Reporte mensual en PDF para el administrador | C46: PB-25 (1.ª versión) | E46: Álvaro Jaña | F46: Hecho | G46: 46293
A47: T1-28 | B47: Reglas del repositorio por escrito (CONTRIBUTING.md y CLAUDE.md) | C47: Transversal | E47: Álvaro Jaña | F47: Hecho | G47: 46294 | H47: PR #7, #8, #11
A48: T1-29 | B48: Nombre visible de la app: RecyTrack | C48: PB-41 (1.ª versión) | E48: Álvaro Jaña | F48: Hecho | G48: 46294 | H48: PR #10
A49: T1-30 | B49: Informe 1.5, justificación de tecnologías y presentaciones con el modelo de tres roles | C49: Documentación | E49: Matías Bustamante | F49: Hecho | G49: 46295 | H49: PR #14, #16, #18
A50: T1-31 | B50: Diagramas de casos de uso y diagrama general de casos de uso | C50: Documentación | E50: Matías Bustamante | F50: Hecho | G50: 46295 | H50: PR #14, #18
A51: T1-32 | B51: Diagrama de arquitectura general | C51: Documentación | E51: Matías Bustamante | F51: Hecho | G51: 46295 | H51: PR #20
A52: T1-33 | B52: Inicio de sesión con Microsoft y su configuración documentada | C52: PB-04 | E52: Álvaro Jaña | F52: Hecho | G52: 46295 | H52: PR #23
A53: T1-34 | B53: Mostrar el rol de quien recicla como colaborador | C53: PB-41 (1.ª versión) | E53: Matías Bustamante | F53: Hecho | G53: 46295 | H53: PR #25
A54: T1-35 | B54: Pull requests sin issue y aprobación por cualquier integrante | C54: Transversal | E54: Álvaro Jaña | F54: Hecho | G54: 46298 | H54: PR #26
A56: Tareas y fechas tomadas del historial del repositorio (commits y pull requests).

Sheet S2
A1: RecyTrack · Sprint Backlog · Sprint 2
A3: Semanas | B3: 7 y 8
A4: Fechas | B4: 5 de octubre al 16 de octubre de 2026
A5: Objetivo del sprint | B5: Que el administrador pueda configurar la planta desde el panel web: crear las áreas, registrar los contenedores de cada punto limpio con sus QR, ver a las personas por área y asignar al validador y su suplente.
A6: Estado del sprint | B6: Cerrado
A7: Puntos comprometidos | B7: =SUM(D12:D18) -> 31
A8: Puntos terminados | B8: =SUMIF(F12:F18,"Hecho",D12:D18) -> 0
A9: Avance | B9: =IF(B7=0,0,B8/B7) -> 0
A10: Historias del sprint | J10: Burndown (puntos restantes)
A11: ID | B11: Historia de usuario | C11: Prioridad | D11: Puntos | E11: Responsable | F11: Estado | G11: Fecha de término | H11: Criterios de aceptación | J11: Día | K11: Fecha | L11: Ideal | M11: Real | N11: Calculado
A12: PB-06 | B12: Como equipo de desarrollo, quiero el modelo de planta, áreas y contenedores con punto limpio, con las reglas del administrador de planta, para que el panel guarde la configuración de forma segura. | C12: Must | D12: 8 | E12: Vicente Torres y Álvaro Jaña | F12: Hecho | G12: 46301 | H12: Existen las colecciones de planta y áreas. Solo el administrador de la planta escribe áreas, contenedores y asignaciones. Las pruebas de reglas pasan contra el emulador. | J12: 1 | K12: 46300 | L12: =$B$7*(9-J12)/8 -> 31 | M12: 31 | N12: =$B$7-SUMIFS($D$12:$D$18,$F$12:$F$18,"Hecho",$G$12:$G$18,"<="&K12) -> 31
A13: PB-07 | B13: Como administrador, quiero un panel de escritorio con menú lateral al entrar desde el computador, para gestionar el programa con comodidad. | C13: Must | D13: 5 | E13: Álvaro Jaña | F13: Hecho | G13: 46302 | H13: Al entrar con rol administrador en una pantalla ancha se muestra el panel. Vive en la misma app. | J13: 2 | K13: 46301 | L13: =$B$7*(9-J13)/8 -> 27.125 | M13: 23 | N13: =$B$7-SUMIFS($D$12:$D$18,$F$12:$F$18,"Hecho",$G$12:$G$18,"<="&K13) -> 31
A14: PB-08 | B14: Como administrador, quiero crear las áreas de la planta con su código de ingreso y su dotación, para medir la participación de cada una. | C14: Must | D14: 3 | E14: Álvaro Jaña | F14: Hecho | G14: 46302 | H14: Cada área tiene nombre, código único y dotación. El código no se repite entre áreas. | J14: 3 | K14: 46302 | L14: =$B$7*(9-J14)/8 -> 23.25 | M14: 0 | N14: =$B$7-SUMIFS($D$12:$D$18,$F$12:$F$18,"Hecho",$G$12:$G$18,"<="&K14) -> 31
A15: PB-09 | B15: Como administrador, quiero crear contenedores indicando su punto limpio y material, e imprimir su QR, para instalarlos en la planta. | C15: Must | D15: 5 | E15: Álvaro Jaña | F15: Hecho | G15: 46302 | H15: Cada contenedor tiene código aleatorio, punto limpio y material (o mixto). El QR se imprime con el código visible debajo. | J15: 4 | K15: 46303 | L15: =$B$7*(9-J15)/8 -> 19.375 | M15: 0 | N15: =$B$7-SUMIFS($D$12:$D$18,$F$12:$F$18,"Hecho",$G$12:$G$18,"<="&K15) -> 31
A16: PB-10 | B16: Como administrador, quiero ver la lista de colaboradores con su área y último depósito, y poder cambiarlos de área, para mantener los datos al día. | C16: Must | D16: 5 | E16: Álvaro Jaña | F16: Hecho | G16: 46302 | H16: Lista filtrable por área. Solo el administrador puede cambiar el área de una persona. | J16: 5 | K16: 46304 | L16: =$B$7*(9-J16)/8 -> 15.5 | M16: 0 | N16: =$B$7-SUMIFS($D$12:$D$18,$F$12:$F$18,"Hecho",$G$12:$G$18,"<="&K16) -> 31
A17: PB-11 | B17: Como administrador, quiero asignar al validador y a su suplente desde el panel, para que la ronda no dependa de una sola persona. | C17: Must | D17: 3 | E17: Álvaro Jaña | F17: Hecho | G17: 46302 | H17: Se elige titular y suplente entre los colaboradores. El cambio se refleja en sus permisos. | J17: 6 | K17: 46308 | L17: =$B$7*(9-J17)/8 -> 11.625 | M17: 0 | N17: =$B$7-SUMIFS($D$12:$D$18,$F$12:$F$18,"Hecho",$G$12:$G$18,"<="&K17) -> 31
A18: PB-12 | B18: Como administrador, quiero cambiar el código de un contenedor si se filtra, para que no se registre desde otro lugar. | C18: Should | D18: 2 | E18: Álvaro Jaña | F18: Hecho | G18: 46302 | H18: El código anterior queda inactivo y el nuevo QR se puede imprimir. | J18: 7 | K18: 46309 | L18: =$B$7*(9-J18)/8 -> 7.75 | M18: 0 | N18: =$B$7-SUMIFS($D$12:$D$18,$F$12:$F$18,"Hecho",$G$12:$G$18,"<="&K18) -> 31
J19: 8 | K19: 46310 | L19: =$B$7*(9-J19)/8 -> 3.875 | M19: 0 | N19: =$B$7-SUMIFS($D$12:$D$18,$F$12:$F$18,"Hecho",$G$12:$G$18,"<="&K19) -> 31
A20: Tareas | J20: 9 | K20: 46311 | L20: =$B$7*(9-J20)/8 -> 0 | M20: 0 | N20: =$B$7-SUMIFS($D$12:$D$18,$F$12:$F$18,"Hecho",$G$12:$G$18,"<="&K20) -> 31
A21: Tarea | B21: Descripción | C21: Historia | D21: Horas est. | E21: Responsable | F21: Estado | G21: Fecha | H21: Issue / PR · Notas | J21: Real: anotar cada día el valor de Calculado. Feriados excluidos.
A22: T2-01 | B22: Definir los tipos de planta, área y contenedor con punto limpio en tipos.ts | C22: PB-06 | E22: Vicente Torres | F22: Hecho | G22: 46300 | H22: PR #38
A23: T2-02 | B23: Servicios de lectura y escritura de la planta y sus áreas | C23: PB-06 | E23: Vicente Torres | F23: Hecho | G23: 46300 | H23: PR #38
A24: T2-03 | B24: Reglas: el administrador de planta escribe áreas, contenedores y asignaciones solo de su planta | C24: PB-06 | E24: Álvaro Jaña | F24: Hecho | G24: 46300 | H24: PR #39
A25: T2-04 | B25: Pruebas de reglas para áreas y contenedores (casos permitidos y rechazados) | C25: PB-06 | E25: Álvaro Jaña | F25: Hecho | G25: 46300 | H25: PR #39
A26: T2-05 | B26: Crear la planta de prueba y la cuenta de administrador en la consola de Firebase | C26: PB-06 | E26: Álvaro Jaña | F26: Por hacer
A27: T2-06 | B27: Mostrar el diseño de escritorio cuando entra un administrador en una pantalla ancha | C27: PB-07 | E27: Álvaro Jaña | F27: Hecho | G27: 46302 | H27: PR #43
A28: T2-07 | B28: Menú lateral con las secciones del sprint: Áreas, Contenedores y QR, Personas | C28: PB-07 | E28: Álvaro Jaña | F28: Hecho | G28: 46302 | H28: PR #43
A29: T2-08 | B29: Componentes base del panel (tablas, formularios, botones) a partir de los existentes | C29: PB-07 | E29: Álvaro Jaña | F29: Hecho | G29: 46302 | H29: PR #43
A30: T2-09 | B30: Formulario para crear un área con nombre y dotación, con código de ingreso generado | C30: PB-08 | E30: Álvaro Jaña | F30: Hecho | G30: 46302 | H30: PR #44
A31: T2-10 | B31: Lista de áreas con su código y dotación, con edición | C31: PB-08 | E31: Álvaro Jaña | F31: Hecho | G31: 46302 | H31: PR #44
A32: T2-11 | B32: Regla y prueba: el código de un área no se repite | C32: PB-08 | E32: Vicente Torres | F32: Por hacer | H32: Las reglas no verifican que el código del área no se repita; pasa al S3
A33: T2-12 | B33: Llevar la gestión de contenedores al panel agregando el punto limpio | C33: PB-09 | E33: Álvaro Jaña | F33: Hecho | G33: 46302 | H33: PR #44
A34: T2-13 | B34: Hoja de impresión de QR con el código visible bajo cada uno | C34: PB-09 | E34: Álvaro Jaña | F34: Hecho | G34: 46302 | H34: PR #44
A35: T2-14 | B35: Desactivar un contenedor desde el panel | C35: PB-09 | E35: Álvaro Jaña | F35: Hecho | G35: 46302 | H35: PR #44
A36: T2-15 | B36: Consulta de colaboradores de la planta con su área y último depósito | C36: PB-10 | E36: Álvaro Jaña | F36: Hecho | G36: 46302 | H36: PR #44
A37: T2-16 | B37: Tabla de personas filtrable por área | C37: PB-10 | E37: Álvaro Jaña | F37: Hecho | G37: 46302 | H37: PR #44
A38: T2-17 | B38: Cambiar de área a un colaborador, con regla que solo lo permite al administrador | C38: PB-10 | E38: Álvaro Jaña | F38: Hecho | G38: 46302 | H38: Regla en PR #39 y pantalla en PR #44
A39: T2-18 | B39: Selector de validador titular y suplente en la sección Personas | C39: PB-11 | E39: Álvaro Jaña | F39: Hecho | G39: 46302 | H39: PR #44
A40: T2-19 | B40: Guardar la asignación en la planta y regla que da el permiso de validador | C40: PB-11 | E40: Álvaro Jaña | F40: Hecho | G40: 46302 | H40: El permiso queda en el rol del perfil (PR #39); selector en PR #44
A41: T2-20 | B41: Llevar el cambio de código al panel y comprobar que el anterior queda inactivo | C41: PB-12 | E41: Álvaro Jaña | F41: Hecho | G41: 46302 | H41: PR #44
...

Sheet S3
A1: RecyTrack · Sprint Backlog · Sprint 3
A3: Semanas | B3: 9 y 10
A4: Fechas | B4: 19 de octubre al 30 de octubre de 2026
A5: Objetivo del sprint | B5: Que el colaborador registre en cualquier punto limpio sumando a su área, y que el validador haga la ronda desde su propia vista.
A6: Estado del sprint | B6: Planificado
A7: Puntos comprometidos | B7: =SUM(D12:D20) -> 33
A8: Puntos terminados | B8: =SUMIF(F12:F20,"Hecho",D12:D20) -> 0
A9: Avance | B9: =IF(B7=0,0,B8/B7) -> 0
A10: Historias del sprint | J10: Burndown (puntos restantes)
A11: ID | B11: Historia de usuario | C11: Prioridad | D11: Puntos | E11: Responsable | F11: Estado | G11: Fecha de término | H11: Criterios de aceptación | J11: Día | K11: Fecha | L11: Ideal | M11: Real | N11: Calculado
A12: PB-13 | B12: Como colaborador, quiero unirme a mi área con el código que me entrega el administrador, para que mis depósitos sumen a mi área. | C12: Must | D12: 5 | E12: Álvaro Jaña | F12: Hecho | G12: 46302 | H12: Un código inválido muestra un error claro. Un colaborador pertenece a una sola área. | J12: 1 | K12: 46314 | L12: =$B$7*(10-J12)/9 -> 33 | N12: =$B$7-SUMIFS($D$12:$D$20,$F$12:$F$20,"Hecho",$G$12:$G$20,"<="&K12) -> 33
A13: PB-14 | B13: Como colaborador, quiero crear mi cuenta sin elegir un rol, para que el registro sea más simple y nadie se asigne permisos. | C13: Must | D13: 1 | E13: Vicente Torres y Álvaro Jaña | F13: Hecho | G13: 46302 | H13: El registro no muestra selector de rol. Toda cuenta nueva nace como colaborador. | J13: 2 | K13: 46315 | L13: =$B$7*(10-J13)/9 -> 29.333333 | N13: =$B$7-SUMIFS($D$12:$D$20,$F$12:$F$20,"Hecho",$G$12:$G$20,"<="&K13) -> 33
A14: PB-15 | B14: Como colaborador, quiero que mis depósitos se guarden sin mi nombre, para que mis compañeros solo vean los totales de mi área. | C14: Must | D14: 3 | E14: Vicente Torres | F14: Hecho | G14: 46301 | H14: El registro guarda el id del colaborador, la planta y el área, sin nombre. Solo el administrador puede leer los perfiles de su planta. | J14: 3 | K14: 46316 | L14: =$B$7*(10-J14)/9 -> 25.666667 | N14: =$B$7-SUMIFS($D$12:$D$20,$F$12:$F$20,"Hecho",$G$12:$G$20,"<="&K14) -> 33
A15: PB-16 | B15: Como colaborador, quiero escanear el QR del contenedor, para registrar mi depósito sin escribir nada. | C15: Must | D15: 5 | E15: Álvaro Jaña | F15: Hecho | G15: 46301 | H15: La cámara lee el QR en el navegador. El contenedor se valida contra la planta. El depósito queda pendiente. | J15: 4 | K15: 46317 | L15: =$B$7*(10-J15)/9 -> 22 | N15: =$B$7-SUMIFS($D$12:$D$20,$F$12:$F$20,"Hecho",$G$12:$G$20,"<="&K15) -> 33
A16: PB-17 | B16: Como equipo de desarrollo, quiero que cada depósito sume al área de quien lo registra y no al contenedor, para que los puntos limpios se compartan entre áreas. | C16: Must | D16: 3 | E16: Vicente Torres | F16: Hecho | G16: 46301 | H16: Un depósito en cualquier contenedor de la planta suma al área del colaborador. | J16: 5 | K16: 46318 | L16: =$B$7*(10-J16)/9 -> 18.333333 | N16: =$B$7-SUMIFS($D$12:$D$20,$F$12:$F$20,"Hecho",$G$12:$G$20,"<="&K16) -> 33
A17: PB-18 | B17: Como equipo de desarrollo, quiero las reglas de seguridad del validador, para que solo él pueda validar o rechazar y solo en su planta. | C17: Must | D17: 5 | E17: Álvaro Jaña | F17: Hecho | G17: 46301 | H17: Las reglas permiten al validador pasar depósitos de pendiente a validado o rechazado y nada más. Pruebas de reglas pasan. | J17: 6 | K17: 46321 | L17: =$B$7*(10-J17)/9 -> 14.666667 | N17: =$B$7-SUMIFS($D$12:$D$20,$F$12:$F$20,"Hecho",$G$12:$G$20,"<="&K17) -> 33
A18: PB-19 | B18: Como validador, quiero ver los depósitos pendientes agrupados por contenedor, para revisarlos en una sola pasada. | C18: Must | D18: 3 | E18: Álvaro Jaña | F18: Hecho | G18: 46302 | H18: Cada contenedor muestra cuántos depósitos tiene y sus tallas. No se valida bolsa por bolsa. | J18: 7 | K18: 46322 | L18: =$B$7*(10-J18)/9 -> 11 | N18: =$B$7-SUMIFS($D$12:$D$20,$F$12:$F$20,"Hecho",$G$12:$G$20,"<="&K18) -> 33
A19: PB-20 | B19: Como validador, quiero marcar cada contenedor como Conforme, Con observación o Sin material, para registrar lo que encontré. | C19: Must | D19: 3 | E19: Álvaro Jaña | F19: Hecho | G19: 46302 | H19: Cada resultado se guarda en una escritura atómica. Con observación pide el material encontrado. Sin material rechaza los depósitos. | J19: 8 | K19: 46323 | L19: =$B$7*(10-J19)/9 -> 7.3333333 | N19: =$B$7-SUMIFS($D$12:$D$20,$F$12:$F$20,"Hecho",$G$12:$G$20,"<="&K19) -> 33
A20: PB-21 | B20: Como validador, quiero una vista que solo muestre la validación, para no confundirme con funciones de administración. | C20: Must | D20: 5 | E20: Álvaro Jaña | F20: Hecho | G20: 46302 | H20: Al entrar con rol validador solo se ve la ronda. No hay acceso al panel. | J20: 9 | K20: 46324 | L20: =$B$7*(10-J20)/9 -> 3.6666667 | N20: =$B$7-SUMIFS($D$12:$D$20,$F$12:$F$20,"Hecho",$G$12:$G$20,"<="&K20) -> 33
J21: 10 | K21: 46325 | L21: =$B$7*(10-J21)/9 -> 0 | N21: =$B$7-SUMIFS($D$12:$D$20,$F$12:$F$20,"Hecho",$G$12:$G$20,"<="&K21) -> 33
A22: Tareas | J22: Real: anotar cada día el valor de Calculado. Feriados excluidos.
A23: Tarea | B23: Descripción | C23: Historia | D23: Horas est. | E23: Responsable | F23: Estado | G23: Fecha | H23: Issue / PR · Notas
A24: T3-01
A25: T3-02
A26: T3-03
A27: T3-04
A28: T3-05
A29: T3-06
A30: T3-07
A31: T3-08
A32: T3-09
A33: T3-10
A34: T3-11
A35: T3-12
A37: Las tareas se definen en la planificación del sprint, a partir de las historias comprometidas.

Sheet S4
A1: RecyTrack · Sprint Backlog · Sprint 4
A3: Semanas | B3: 11 y 12
A4: Fechas | B4: 2 de noviembre al 13 de noviembre de 2026
A5: Objetivo del sprint | B5: Cerrar la cadena con el registro de retiros desde el panel, emitir el reporte y los certificados del mes, y dejar la planta lista para iniciar el piloto.
A6: Estado del sprint | B6: Planificado
A7: Puntos comprometidos | B7: =SUM(D12:D20) -> 30
A8: Puntos terminados | B8: =SUMIF(F12:F20,"Hecho",D12:D20) -> 0
A9: Avance | B9: =IF(B7=0,0,B8/B7) -> 0
A10: Historias del sprint | J10: Burndown (puntos restantes)
A11: ID | B11: Historia de usuario | C11: Prioridad | D11: Puntos | E11: Responsable | F11: Estado | G11: Fecha de término | H11: Criterios de aceptación | J11: Día | K11: Fecha | L11: Ideal | M11: Real | N11: Calculado
A12: PB-22 | B12: Como administrador, quiero registrar cada retiro con fecha, quién retira, número de guía, contenedores y peso opcional, para certificar en ese mismo registro los depósitos validados. | C12: Must | D12: 8 | E12: Álvaro Jaña | F12: Hecho | G12: 46302 | H12: El retiro y la certificación se guardan juntos o no se guarda nada. Sin guía se puede registrar igual. | J12: 1 | K12: 46328 | L12: =$B$7*(10-J12)/9 -> 30 | N12: =$B$7-SUMIFS($D$12:$D$20,$F$12:$F$20,"Hecho",$G$12:$G$20,"<="&K12) -> 30
A13: PB-23 | B13: Como equipo de desarrollo, quiero eliminar la vista y el código de gestor, para que la app quede con los tres roles definidos. | C13: Must | D13: 2 | E13: Vicente Torres y Álvaro Jaña | F13: Hecho | G13: 46301 | H13: No existe pantalla ni rol de gestor. Las reglas no aceptan ese rol. | J13: 2 | K13: 46329 | L13: =$B$7*(10-J13)/9 -> 26.666667 | N13: =$B$7-SUMIFS($D$12:$D$20,$F$12:$F$20,"Hecho",$G$12:$G$20,"<="&K13) -> 30
A14: PB-24 | B14: Como colaborador, quiero descargar mi certificado mensual en PDF, para tener evidencia de lo que reciclé. | C14: Must | D14: 3 | E14: Vicente Torres | F14: Hecho | G14: 46301 | H14: Incluye kilos del mes, desglose por material, código único y detalle de cada depósito. | J14: 3 | K14: 46330 | L14: =$B$7*(10-J14)/9 -> 23.333333 | N14: =$B$7-SUMIFS($D$12:$D$20,$F$12:$F$20,"Hecho",$G$12:$G$20,"<="&K14) -> 30
A15: PB-25 | B15: Como administrador, quiero descargar el reporte mensual de la planta en PDF, para presentarlo en la gestión de sustentabilidad. | C15: Must | D15: 5 | E15: Álvaro Jaña | F15: Hecho | G15: 46302 | H15: Incluye participación por área, kilos por material, tiempos de cada etapa y observaciones. Se genera sin intervención manual. | J15: 4 | K15: 46331 | L15: =$B$7*(10-J15)/9 -> 20 | N15: =$B$7-SUMIFS($D$12:$D$20,$F$12:$F$20,"Hecho",$G$12:$G$20,"<="&K15) -> 30
A16: PB-26 | B16: Como equipo de desarrollo, quiero borrar los datos y cuentas de prueba, para partir el piloto en limpio. | C16: Must | D16: 2 | F16: Por hacer | H16: Respaldo exportado antes de borrar. La base queda sin datos de prueba. | J16: 5 | K16: 46332 | L16: =$B$7*(10-J16)/9 -> 16.666667 | N16: =$B$7-SUMIFS($D$12:$D$20,$F$12:$F$20,"Hecho",$G$12:$G$20,"<="&K16) -> 30
A17: PB-27 | B17: Como administrador de la viña, quiero que mi planta, mi cuenta, las áreas, los contenedores y el validador queden configurados, para empezar el piloto. | C17: Must | D17: 3 | F17: Por hacer | H17: La contraparte entra al panel y ve su planta lista. | J17: 6 | K17: 46335 | L17: =$B$7*(10-J17)/9 -> 13.333333 | N17: =$B$7-SUMIFS($D$12:$D$20,$F$12:$F$20,"Hecho",$G$12:$G$20,"<="&K17) -> 30
A18: PB-28 | B18: Como administrador, quiero que al registrar el retiro se cierren las observaciones de esos contenedores, para no arrastrarlas al mes siguiente. | C18: Should | D18: 2 | E18: Álvaro Jaña | F18: Hecho | G18: 46302 | H18: Las observaciones de los contenedores retirados quedan atendidas con el código del retiro. | J18: 7 | K18: 46336 | L18: =$B$7*(10-J18)/9 -> 10 | N18: =$B$7-SUMIFS($D$12:$D$20,$F$12:$F$20,"Hecho",$G$12:$G$20,"<="&K18) -> 30
A19: PB-29 | B19: Como administrador, quiero ver los retiros del mes con su guía y si el peso es estimado o verificado, para respaldar el reporte. | C19: Should | D19: 3 | E19: Álvaro Jaña | F19: Hecho | G19: 46302 | H19: Lista ordenada por fecha. Un retiro con peso se marca como verificado. | J19: 8 | K19: 46337 | L19: =$B$7*(10-J19)/9 -> 6.6666667 | N19: =$B$7-SUMIFS($D$12:$D$20,$F$12:$F$20,"Hecho",$G$12:$G$20,"<="&K19) -> 30
A20: PB-30 | B20: Como validador, quiero recibir un aviso cuando hay depósitos por validar, para hacer la ronda a tiempo. | C20: Should | D20: 2 | E20: Álvaro Jaña | F20: Hecho | G20: 46302 | H20: El aviso aparece en la campana y como banner al abrir la app. | J20: 9 | K20: 46338 | L20: =$B$7*(10-J20)/9 -> 3.3333333 | N20: =$B$7-SUMIFS($D$12:$D$20,$F$12:$F$20,"Hecho",$G$12:$G$20,"<="&K20) -> 30
J21: 10 | K21: 46339 | L21: =$B$7*(10-J21)/9 -> 0 | N21: =$B$7-SUMIFS($D$12:$D$20,$F$12:$F$20,"Hecho",$G$12:$G$20,"<="&K21) -> 30
A22: Tareas | J22: Real: anotar cada día el valor de Calculado. Feriados excluidos.
A23: Tarea | B23: Descripción | C23: Historia | D23: Horas est. | E23: Responsable | F23: Estado | G23: Fecha | H23: Issue / PR · Notas
A24: T4-01
A25: T4-02
A26: T4-03
A27: T4-04
A28: T4-05
A29: T4-06
A30: T4-07
A31: T4-08
A32: T4-09
A33: T4-10
A34: T4-11
A35: T4-12
A37: Las tareas se definen en la planificación del sprint, a partir de las historias comprometidas.

Sheet S5
A1: RecyTrack · Sprint Backlog · Sprint 5
A3: Semanas | B3: 13 y 14
A4: Fechas | B4: 16 de noviembre al 27 de noviembre de 2026
A5: Objetivo del sprint | B5: Completar el panel con resumen y rondas, y activar las campañas y el ranking de áreas por participación, con el piloto en curso.
A6: Estado del sprint | B6: Planificado
A7: Puntos comprometidos | B7: =SUM(D12:D18) -> 25
A8: Puntos terminados | B8: =SUMIF(F12:F18,"Hecho",D12:D18) -> 0
A9: Avance | B9: =IF(B7=0,0,B8/B7) -> 0
A10: Historias del sprint | J10: Burndown (puntos restantes)
A11: ID | B11: Historia de usuario | C11: Prioridad | D11: Puntos | E11: Responsable | F11: Estado | G11: Fecha de término | H11: Criterios de aceptación | J11: Día | K11: Fecha | L11: Ideal | M11: Real | N11: Calculado
A12: PB-31 | B12: Como colaborador, quiero ver el ranking de áreas ordenado por participación, para saber cómo va mi área frente a las demás. | C12: Must | D12: 5 | E12: Álvaro Jaña | F12: Hecho | G12: 46302 | H12: Ordena por porcentaje de la dotación que recicló en el mes. Muestra EcoPuntos por área. No muestra personas. | J12: 1 | K12: 46342 | L12: =$B$7*(10-J12)/9 -> 25 | N12: =$B$7-SUMIFS($D$12:$D$18,$F$12:$F$18,"Hecho",$G$12:$G$18,"<="&K12) -> 25
A13: PB-32 | B13: Como administrador, quiero crear una campaña con meta de participación, incentivo y fecha de término, para motivar a las áreas. | C13: Must | D13: 5 | E13: Álvaro Jaña | F13: Hecho | G13: 46302 | H13: Una campaña activa por planta. La meta nunca se expresa en kilos. | J13: 2 | K13: 46343 | L13: =$B$7*(10-J13)/9 -> 22.222222 | N13: =$B$7-SUMIFS($D$12:$D$18,$F$12:$F$18,"Hecho",$G$12:$G$18,"<="&K13) -> 25
A14: PB-33 | B14: Como administrador, quiero ver un resumen del mes con participación, depósitos validados, kilos estimados, rondas y observaciones, para saber cómo va el programa. | C14: Must | D14: 5 | E14: Álvaro Jaña | F14: Hecho | G14: 46302 | H14: Los indicadores coinciden con el reporte mensual del mismo período. | J14: 3 | K14: 46344 | L14: =$B$7*(10-J14)/9 -> 19.444444 | N14: =$B$7-SUMIFS($D$12:$D$18,$F$12:$F$18,"Hecho",$G$12:$G$18,"<="&K14) -> 25
A15: PB-34 | B15: Como colaborador, quiero ver en Inicio el lugar de mi área y el incentivo vigente, para saber por qué estamos compitiendo. | C15: Should | D15: 3 | E15: Álvaro Jaña | F15: Hecho | G15: 46302 | H15: Tarjeta con área, posición en el ranking, avance de la campaña e incentivo. | J15: 4 | K15: 46345 | L15: =$B$7*(10-J15)/9 -> 16.666667 | N15: =$B$7-SUMIFS($D$12:$D$18,$F$12:$F$18,"Hecho",$G$12:$G$18,"<="&K15) -> 25
A16: PB-35 | B16: Como administrador, quiero ver el calendario de rondas del mes y la ronda de hoy, para saber si el validador está cumpliendo. | C16: Should | D16: 5 | E16: Álvaro Jaña | F16: Hecho | G16: 46302 | H16: Cada día se marca como completado o no según las validaciones registradas. | J16: 5 | K16: 46346 | L16: =$B$7*(10-J16)/9 -> 13.888889 | N16: =$B$7-SUMIFS($D$12:$D$18,$F$12:$F$18,"Hecho",$G$12:$G$18,"<="&K16) -> 25
A17: PB-36 | B17: Como colaborador, quiero seguir teniendo la misión semanal y sus puntos, para tener una meta personal corta. | C17: Could | D17: 1 | E17: Álvaro Jaña | F17: Hecho | G17: 46302 | H17: La misión rota cada semana y se calcula con depósitos no rechazados. | J17: 6 | K17: 46349 | L17: =$B$7*(10-J17)/9 -> 11.111111 | N17: =$B$7-SUMIFS($D$12:$D$18,$F$12:$F$18,"Hecho",$G$12:$G$18,"<="&K17) -> 25
A18: PB-37 | B18: Como administrador que entra desde el celular, quiero un mensaje que me pida abrir el panel en el computador, para no operar en una pantalla pequeña. | C18: Could | D18: 1 | E18: Álvaro Jaña | F18: Hecho | G18: 46302 | H18: En pantallas angostas se muestra el mensaje en lugar del panel. | J18: 7 | K18: 46350 | L18: =$B$7*(10-J18)/9 -> 8.3333333 | N18: =$B$7-SUMIFS($D$12:$D$18,$F$12:$F$18,"Hecho",$G$12:$G$18,"<="&K18) -> 25
J19: 8 | K19: 46351 | L19: =$B$7*(10-J19)/9 -> 5.5555556 | N19: =$B$7-SUMIFS($D$12:$D$18,$F$12:$F$18,"Hecho",$G$12:$G$18,"<="&K19) -> 25
A20: Tareas | J20: 9 | K20: 46352 | L20: =$B$7*(10-J20)/9 -> 2.7777778 | N20: =$B$7-SUMIFS($D$12:$D$18,$F$12:$F$18,"Hecho",$G$12:$G$18,"<="&K20) -> 25
A21: Tarea | B21: Descripción | C21: Historia | D21: Horas est. | E21: Responsable | F21: Estado | G21: Fecha | H21: Issue / PR · Notas | J21: 10 | K21: 46353 | L21: =$B$7*(10-J21)/9 -> 0 | N21: =$B$7-SUMIFS($D$12:$D$18,$F$12:$F$18,"Hecho",$G$12:$G$18,"<="&K21) -> 25
A22: T5-01 | J22: Real: anotar cada día el valor de Calculado. Feriados excluidos.
A23: T5-02
A24: T5-03
A25: T5-04
A26: T5-05
A27: T5-06
A28: T5-07
A29: T5-08
A30: T5-09
A31: T5-10
A32: T5-11
A33: T5-12
A35: Las tareas se definen en la planificación del sprint, a partir de las historias comprometidas.

Sheet S6
A1: RecyTrack · Sprint Backlog · Sprint 6
A3: Semanas | B3: 15 a 17
A4: Fechas | B4: 30 de noviembre al 18 de diciembre de 2026
A5: Objetivo del sprint | B5: Cerrar el piloto, medir las métricas comprometidas, corregir errores y terminar los detalles pendientes.
A6: Estado del sprint | B6: Planificado
A7: Puntos comprometidos | B7: =SUM(D12:D18) -> 20
A8: Puntos terminados | B8: =SUMIF(F12:F18,"Hecho",D12:D18) -> 0
A9: Avance | B9: =IF(B7=0,0,B8/B7) -> 0
A10: Historias del sprint | J10: Burndown (puntos restantes)
A11: ID | B11: Historia de usuario | C11: Prioridad | D11: Puntos | E11: Responsable | F11: Estado | G11: Fecha de término | H11: Criterios de aceptación | J11: Día | K11: Fecha | L11: Ideal | M11: Real | N11: Calculado
A12: PB-38 | B12: Como equipo, quiero ejecutar el plan de pruebas y medir las métricas del piloto, para comprobar si se cumplieron los objetivos. | C12: Must | D12: 5 | F12: Por hacer | H12: Se mide lectura de QR, rondas completadas, tiempo de la cadena, participación por área y documentos emitidos. | J12: 1 | K12: 46356 | L12: =$B$7*(14-J12)/13 -> 20 | N12: =$B$7-SUMIFS($D$12:$D$18,$F$12:$F$18,"Hecho",$G$12:$G$18,"<="&K12) -> 20
A13: PB-39 | B13: Como equipo, quiero corregir los errores que aparezcan en el piloto, para cerrar con un producto estable. | C13: Must | D13: 5 | F13: Por hacer | H13: Los errores reportados quedan registrados y se resuelven por prioridad. | J13: 2 | K13: 46357 | L13: =$B$7*(14-J13)/13 -> 18.461538 | N13: =$B$7-SUMIFS($D$12:$D$18,$F$12:$F$18,"Hecho",$G$12:$G$18,"<="&K13) -> 20
A14: PB-40 | B14: Como administrador, quiero que la masa aparezca como verificada cuando el retiro tiene peso, para no presentar estimaciones como mediciones. | C14: Should | D14: 3 | E14: Álvaro Jaña | F14: Hecho | G14: 46302 | H14: Reporte y certificado distinguen kilos estimados y verificados. | J14: 3 | K14: 46358 | L14: =$B$7*(14-J14)/13 -> 16.923077 | N14: =$B$7-SUMIFS($D$12:$D$18,$F$12:$F$18,"Hecho",$G$12:$G$18,"<="&K14) -> 20
A15: PB-41 | B15: Como colaborador, quiero que toda la app use el nombre RecyTrack y el vocabulario de la planta, para reconocerla como el programa de mi lugar de trabajo. | C15: Should | D15: 3 | E15: Álvaro Jaña | F15: Hecho | G15: 46302 | H15: El nombre RecyTrack aparece en la app, el ícono instalable y los PDF. Todos los textos hablan de colaboradores, áreas y puntos limpios. | J15: 4 | K15: 46359 | L15: =$B$7*(14-J15)/13 -> 15.384615 | N15: =$B$7-SUMIFS($D$12:$D$18,$F$12:$F$18,"Hecho",$G$12:$G$18,"<="&K15) -> 20
A16: PB-42 | B16: Como colaborador, quiero ver mi área en Mi cuenta sin poder cambiarla yo, para que nadie suba la participación cambiándose. | C16: Should | D16: 2 | E16: Vicente Torres y Álvaro Jaña | F16: Hecho | G16: 46302 | H16: Mi cuenta muestra el área sin opción de editarla. Las reglas rechazan que un colaborador cambie su propia área. | J16: 5 | K16: 46360 | L16: =$B$7*(14-J16)/13 -> 13.846154 | N16: =$B$7-SUMIFS($D$12:$D$18,$F$12:$F$18,"Hecho",$G$12:$G$18,"<="&K16) -> 20
A17: PB-43 | B17: Como colaborador del turno de noche, quiero saber que mi depósito se valida en la ronda del día siguiente, para no pensar que se perdió. | C17: Could | D17: 1 | F17: Por hacer | H17: Al registrar fuera del horario de ronda se muestra un aviso breve. | J17: 6 | K17: 46363 | L17: =$B$7*(14-J17)/13 -> 12.307692 | N17: =$B$7-SUMIFS($D$12:$D$18,$F$12:$F$18,"Hecho",$G$12:$G$18,"<="&K17) -> 20
A18: PB-44 | B18: Como administrador de la viña, quiero una dirección web con el nombre RecyTrack, para compartirla con los colaboradores. | C18: Could | D18: 1 | F18: Por hacer | H18: La app responde en un sitio de hosting con el nombre RecyTrack. | J18: 7 | K18: 46365 | L18: =$B$7*(14-J18)/13 -> 10.769231 | N18: =$B$7-SUMIFS($D$12:$D$18,$F$12:$F$18,"Hecho",$G$12:$G$18,"<="&K18) -> 20
J19: 8 | K19: 46366 | L19: =$B$7*(14-J19)/13 -> 9.2307692 | N19: =$B$7-SUMIFS($D$12:$D$18,$F$12:$F$18,"Hecho",$G$12:$G$18,"<="&K19) -> 20
A20: Tareas | J20: 9 | K20: 46367 | L20: =$B$7*(14-J20)/13 -> 7.6923077 | N20: =$B$7-SUMIFS($D$12:$D$18,$F$12:$F$18,"Hecho",$G$12:$G$18,"<="&K20) -> 20
A21: Tarea | B21: Descripción | C21: Historia | D21: Horas est. | E21: Responsable | F21: Estado | G21: Fecha | H21: Issue / PR · Notas | J21: 10 | K21: 46370 | L21: =$B$7*(14-J21)/13 -> 6.1538462 | N21: =$B$7-SUMIFS($D$12:$D$18,$F$12:$F$18,"Hecho",$G$12:$G$18,"<="&K21) -> 20
A22: T6-01 | J22: 11 | K22: 46371 | L22: =$B$7*(14-J22)/13 -> 4.6153846 | N22: =$B$7-SUMIFS($D$12:$D$18,$F$12:$F$18,"Hecho",$G$12:$G$18,"<="&K22) -> 20
A23: T6-02 | J23: 12 | K23: 46372 | L23: =$B$7*(14-J23)/13 -> 3.0769231 | N23: =$B$7-SUMIFS($D$12:$D$18,$F$12:$F$18,"Hecho",$G$12:$G$18,"<="&K23) -> 20
A24: T6-03 | J24: 13 | K24: 46373 | L24: =$B$7*(14-J24)/13 -> 1.5384615 | N24: =$B$7-SUMIFS($D$12:$D$18,$F$12:$F$18,"Hecho",$G$12:$G$18,"<="&K24) -> 20
A25: T6-04 | J25: 14 | K25: 46374 | L25: =$B$7*(14-J25)/13 -> 0 | N25: =$B$7-SUMIFS($D$12:$D$18,$F$12:$F$18,"Hecho",$G$12:$G$18,"<="&K25) -> 20
A26: T6-05 | J26: Real: anotar cada día el valor de Calculado. Feriados excluidos.
A27: T6-06
A28: T6-07
A29: T6-08
A30: T6-09
A31: T6-10
A32: T6-11
A33: T6-12
A35: Las tareas se definen en la planificación del sprint, a partir de las historias comprometidas.
